<?xml version="1.0" ?>
<robot name="gripperone" xmlns:xacro="http://www.ros.org/wiki/xacro">

<xacro:include filename="$(find gripperone_description)/urdf/materials.xacro" />
<xacro:include filename="$(find gripperone_description)/urdf/gripperone.trans" />
<xacro:include filename="$(find gripperone_description)/urdf/gripperone.gazebo" />
<link name="base_link">
  <inertial>
    <origin rpy="0 0 0" xyz="0.013100742072346745 3.232305809001723e-17 0.128434649849364"/>
    <mass value="141.36352349403447"/>
    <inertia ixx="2.770677" ixy="0.0" ixz="-0.206615" iyy="3.022714" iyz="0.0" izz="2.748975"/>
  </inertial>
  <visual>
    <origin rpy="0 0 0" xyz="0 0 0"/>
    <geometry>
      <mesh filename="package://gripperone_description/meshes/base_link.stl" scale="0.001 0.001 0.001"/>
    </geometry>
    <material name="silver"/>
  </visual>
  <collision>
    <origin rpy="0 0 0" xyz="0 0 0"/>
    <geometry>
      <mesh filename="package://gripperone_description/meshes/base_link.stl" scale="0.001 0.001 0.001"/>
    </geometry>
  </collision>
</link>

<link name="link1_1">
  <inertial>
    <origin rpy="0 0 0" xyz="7.96052754045408e-09 1.1704235139557597e-07 0.05605079320414236"/>
    <mass value="113.94031727647719"/>
    <inertia ixx="2.418287" ixy="0.0" ixz="-0.0" iyy="2.208887" iyz="-1e-06" izz="0.859498"/>
  </inertial>
  <visual>
    <origin rpy="0 0 0" xyz="-0.0 -0.0 -0.37"/>
    <geometry>
      <mesh filename="package://gripperone_description/meshes/link1_1.stl" scale="0.001 0.001 0.001"/>
    </geometry>
    <material name="silver"/>
  </visual>
  <collision>
    <origin rpy="0 0 0" xyz="-0.0 -0.0 -0.37"/>
    <geometry>
      <mesh filename="package://gripperone_description/meshes/link1_1.stl" scale="0.001 0.001 0.001"/>
    </geometry>
  </collision>
</link>

<link name="link2_1">
  <inertial>
    <origin rpy="0 0 0" xyz="0.5493289971509847 -0.09000000753235006 0.5305570384816423"/>
    <mass value="96.27136209757765"/>
    <inertia ixx="3.396419" ixy="0.0" ixz="-0.0" iyy="4.009316" iyz="0.0" izz="1.077023"/>
  </inertial>
  <visual>
    <origin rpy="0 0 0" xyz="0.548975 -0.09 -0.212975"/>
    <geometry>
      <mesh filename="package://gripperone_description/meshes/link2_1.stl" scale="0.001 0.001 0.001"/>
    </geometry>
    <material name="silver"/>
  </visual>
  <collision>
    <origin rpy="0 0 0" xyz="0.548975 -0.09 -0.212975"/>
    <geometry>
      <mesh filename="package://gripperone_description/meshes/link2_1.stl" scale="0.001 0.001 0.001"/>
    </geometry>
  </collision>
</link>

<link name="link3_1">
  <inertial>
    <origin rpy="0 0 0" xyz="1.044797001497465 -0.21075740777313084 0.6188289253614156"/>
    <mass value="89.40771247233054"/>
    <inertia ixx="2.454822" ixy="0.0" ixz="-0.0" iyy="0.570231" iyz="0.274684" izz="2.203132"/>
  </inertial>
  <visual>
    <origin rpy="0 0 0" xyz="1.048621 -0.089646 -0.548975"/>
    <geometry>
      <mesh filename="package://gripperone_description/meshes/link3_1.stl" scale="0.001 0.001 0.001"/>
    </geometry>
    <material name="silver"/>
  </visual>
  <collision>
    <origin rpy="0 0 0" xyz="1.048621 -0.089646 -0.548975"/>
    <geometry>
      <mesh filename="package://gripperone_description/meshes/link3_1.stl" scale="0.001 0.001 0.001"/>
    </geometry>
  </collision>
</link>

<link name="link4_1">
  <inertial>
    <origin rpy="0 0 0" xyz="-1.4265904594787382e-09 0.0060849484871947634 -0.3504329444028469"/>
    <mass value="67.9097115028488"/>
    <inertia ixx="4.721936" ixy="-0.0" ixz="-0.0" iyy="5.0523" iyz="0.010769" izz="0.494356"/>
  </inertial>
  <visual>
    <origin rpy="0 0 0" xyz="0.003824 0.427705 -1.192626"/>
    <geometry>
      <mesh filename="package://gripperone_description/meshes/link4_1.stl" scale="0.001 0.001 0.001"/>
    </geometry>
    <material name="silver"/>
  </visual>
  <collision>
    <origin rpy="0 0 0" xyz="0.003824 0.427705 -1.192626"/>
    <geometry>
      <mesh filename="package://gripperone_description/meshes/link4_1.stl" scale="0.001 0.001 0.001"/>
    </geometry>
  </collision>
</link>

<link name="link5_1">
  <inertial>
    <origin rpy="0 0 0" xyz="0.3218904956050812 -0.003710721314147347 0.39053282142218665"/>
    <mass value="9.640341866039392"/>
    <inertia ixx="0.052863" ixy="3e-06" ixz="-0.000271" iyy="0.057534" iyz="0.000179" izz="0.017456"/>
  </inertial>
  <visual>
    <origin rpy="0 0 0" xyz="0.32645 0.423881 0.00508"/>
    <geometry>
      <mesh filename="package://gripperone_description/meshes/link5_1.stl" scale="0.001 0.001 0.001"/>
    </geometry>
    <material name="silver"/>
  </visual>
  <collision>
    <origin rpy="0 0 0" xyz="0.32645 0.423881 0.00508"/>
    <geometry>
      <mesh filename="package://gripperone_description/meshes/link5_1.stl" scale="0.001 0.001 0.001"/>
    </geometry>
  </collision>
</link>

<link name="finger1_1">
  <inertial>
    <origin rpy="0 0 0" xyz="-0.048294418604868564 0.0030405265471282195 -0.05130421226060786"/>
    <mass value="0.4623359413194335"/>
    <inertia ixx="0.001069" ixy="6.5e-05" ixz="-0.000864" iyy="0.001847" iyz="7.3e-05" izz="0.000811"/>
  </inertial>
  <visual>
    <origin rpy="0 0 0" xyz="0.035732 0.43251 -0.212317"/>
    <geometry>
      <mesh filename="package://gripperone_description/meshes/finger1_1.stl" scale="0.001 0.001 0.001"/>
    </geometry>
    <material name="silver"/>
  </visual>
  <collision>
    <origin rpy="0 0 0" xyz="0.035732 0.43251 -0.212317"/>
    <geometry>
      <mesh filename="package://gripperone_description/meshes/finger1_1.stl" scale="0.001 0.001 0.001"/>
    </geometry>
  </collision>
</link>

<link name="finger2_1">
  <inertial>
    <origin rpy="0 0 0" xyz="0.04744724710552086 0.003574144409227209 -0.05009911920004462"/>
    <mass value="0.48552512703105344"/>
    <inertia ixx="0.001074" ixy="-5.1e-05" ixz="0.000898" iyy="0.001899" iyz="5.4e-05" izz="0.000871"/>
  </inertial>
  <visual>
    <origin rpy="0 0 0" xyz="-0.023668 0.43251 -0.212162"/>
    <geometry>
      <mesh filename="package://gripperone_description/meshes/finger2_1.stl" scale="0.001 0.001 0.001"/>
    </geometry>
    <material name="silver"/>
  </visual>
  <collision>
    <origin rpy="0 0 0" xyz="-0.023668 0.43251 -0.212162"/>
    <geometry>
      <mesh filename="package://gripperone_description/meshes/finger2_1.stl" scale="0.001 0.001 0.001"/>
    </geometry>
  </collision>
</link>

<joint name="Rev75" type="continuous">
  <origin rpy="0 0 0" xyz="0.0 0.0 0.37"/>
  <parent link="base_link"/>
  <child link="link1_1"/>
  <axis xyz="0.0 0.0 -1.0"/>
</joint>

<joint name="Rev76" type="continuous">
  <origin rpy="0 0 0" xyz="-0.548975 0.09 -0.157025"/>
  <parent link="link1_1"/>
  <child link="link2_1"/>
  <axis xyz="1.0 0.0 -0.0"/>
</joint>

<joint name="Rev77" type="continuous">
  <origin rpy="0 0 0" xyz="-0.499646 -0.000354 0.336"/>
  <parent link="link2_1"/>
  <child link="link3_1"/>
  <axis xyz="1.0 0.0 -0.0"/>
</joint>

<joint name="Rev78" type="continuous">
  <origin rpy="0 0 0" xyz="1.044797 -0.517351 0.643651"/>
  <parent link="link3_1"/>
  <child link="link4_1"/>
  <axis xyz="1.0 0.0 -0.0"/>
</joint>

<joint name="Rev79" type="continuous">
  <origin rpy="0 0 0" xyz="-0.322626 0.003824 -1.197706"/>
  <parent link="link4_1"/>
  <child link="link5_1"/>
  <axis xyz="-1.0 -0.0 0.0"/>
</joint>

<joint name="Rev80" type="continuous">
  <origin rpy="0 0 0" xyz="0.290718 -0.008629 0.217397"/>
  <parent link="link5_1"/>
  <child link="finger1_1"/>
  <axis xyz="-0.0 -1.0 -0.0"/>
</joint>

<joint name="Rev81" type="continuous">
  <origin rpy="0 0 0" xyz="0.350118 -0.008629 0.217242"/>
  <parent link="link5_1"/>
  <child link="finger2_1"/>
  <axis xyz="-0.0 -1.0 -0.0"/>
</joint>

</robot>
